[INFO  2019-10-22 15:20:53 @__init__.py:79] Set root logger. Unset logger with neuralgym.unset_logger().
[INFO  2019-10-22 15:20:53 @__init__.py:80] Saving logging to file: neuralgym_logs/20191022152053183863.
[INFO  2019-10-22 15:20:53 @_internal.py:122]  * Running on http://172.19.140.150:5003/ (Press CTRL+C to quit)
[ERROR 2019-10-22 15:20:58 @app.py:1891] Exception on /inpainting/api/v1.0/order [POST]
Traceback (most recent call last):
  File "/home/data/shared/conda_envs/tf-gpu/lib/python3.6/site-packages/flask/app.py", line 2446, in wsgi_app
    response = self.full_dispatch_request()
  File "/home/data/shared/conda_envs/tf-gpu/lib/python3.6/site-packages/flask/app.py", line 1951, in full_dispatch_request
    rv = self.handle_user_exception(e)
  File "/home/data/shared/conda_envs/tf-gpu/lib/python3.6/site-packages/flask/app.py", line 1820, in handle_user_exception
    reraise(exc_type, exc_value, tb)
  File "/home/data/shared/conda_envs/tf-gpu/lib/python3.6/site-packages/flask/_compat.py", line 39, in reraise
    raise value
  File "/home/data/shared/conda_envs/tf-gpu/lib/python3.6/site-packages/flask/app.py", line 1949, in full_dispatch_request
    rv = self.dispatch_request()
  File "/home/data/shared/conda_envs/tf-gpu/lib/python3.6/site-packages/flask/app.py", line 1935, in dispatch_request
    return self.view_functions[rule.endpoint](**req.view_args)
  File "api.py", line 67, in postJsonHandler_multiprocessing
    Image_inpainting = Image_inpainting()
UnboundLocalError: local variable 'Image_inpainting' referenced before assignment
[INFO  2019-10-22 15:20:58 @_internal.py:122] 172.19.140.253 - - [22/Oct/2019 15:20:58] "[1m[35mPOST /inpainting/api/v1.0/order HTTP/1.1[0m" 500 -
[ERROR 2019-10-22 15:21:01 @app.py:1891] Exception on /inpainting/api/v1.0/order [POST]
Traceback (most recent call last):
  File "/home/data/shared/conda_envs/tf-gpu/lib/python3.6/site-packages/flask/app.py", line 2446, in wsgi_app
    response = self.full_dispatch_request()
  File "/home/data/shared/conda_envs/tf-gpu/lib/python3.6/site-packages/flask/app.py", line 1951, in full_dispatch_request
    rv = self.handle_user_exception(e)
  File "/home/data/shared/conda_envs/tf-gpu/lib/python3.6/site-packages/flask/app.py", line 1820, in handle_user_exception
    reraise(exc_type, exc_value, tb)
  File "/home/data/shared/conda_envs/tf-gpu/lib/python3.6/site-packages/flask/_compat.py", line 39, in reraise
    raise value
  File "/home/data/shared/conda_envs/tf-gpu/lib/python3.6/site-packages/flask/app.py", line 1949, in full_dispatch_request
    rv = self.dispatch_request()
  File "/home/data/shared/conda_envs/tf-gpu/lib/python3.6/site-packages/flask/app.py", line 1935, in dispatch_request
    return self.view_functions[rule.endpoint](**req.view_args)
  File "api.py", line 67, in postJsonHandler_multiprocessing
    Image_inpainting = Image_inpainting()
UnboundLocalError: local variable 'Image_inpainting' referenced before assignment
[INFO  2019-10-22 15:21:01 @_internal.py:122] 172.19.140.253 - - [22/Oct/2019 15:21:01] "[1m[35mPOST /inpainting/api/v1.0/order HTTP/1.1[0m" 500 -
